Workbook
Name Segment_Année: #N/A
Name Segment_Année1: #N/A
Name Segment_Année2: #N/A
Name Segment_Année3: #N/A
Name Segment_Année4: #N/A
Name Segment_Mois: #N/A
Name Segment_Mois1: #N/A
Name Segment_Mois2: #N/A
Name Segment_Mois3: #N/A
Name Segment_Mois4: #N/A
Name Segment1: 'Taux émission CO2e'!$A$5:$D$16
Name Segment2: 'Taux émission CO2e'!$A$20:$D$31

Sheet Import
A1: Date saisie | B1: Mois | C1: Année | D1: Moisannée | E1: Numero ot | F1: Poids OT (kg) | G1: Poids OT (T) | H1: Type transport | I1: % répartition segment 1 | J1: % répartition segment 2 | K1: Tx Segment 1 | L1: Segment 1 Bilan emission CO2 | M1: Tx segment 2 | N1: Segment 2 Bilan emission CO2 | O1: Bilan CO2 | P1: Coût OT (€) | Q1: Lieu depart OT | R1: Lieu arrivee OT | S1: Distance en km
A2: 44200 | B2: =TEXT(A2,"mmmm") -> janvier | C2: =TEXT(A2,"aaaa") -> 2021 | D2: =B2&C2 -> janvier2021 | E2: 1308270 | F2: 185 | G2: =F2/1000 -> 0.185 | H2: AFF | I2: =VLOOKUP(H2,Segment1,2,FALSE) -> 1 | J2: =VLOOKUP(H2,Segment2,2,FALSE) -> 0 | K2: =VLOOKUP(H2,'Taux émission CO2e'!$A$5:$D$16,4,FALSE) -> 0.0674 | L2: =IFERROR(I2*K2*G2*S2,"0") -> 6.7355668 | M2: =VLOOKUP(H2,'Taux émission CO2e'!$A$20:$D$31,4,FALSE) -> 0 | N2: =IFERROR(J2*M2*G2*S2,"0") -> 0 | O2: =L2+N2 -> 6.7355668 | P2: 165 | Q2: 67100 STRASBOURG | R2: 59100ROUBAIX | S2: 540.185
A3: 44200 | B3: =TEXT(A3,"mmmm") -> janvier | C3: =TEXT(A3,"aaaa") -> 2021 | D3: =B3&C3 -> janvier2021 | E3: 1308264 | F3: 452 | G3: =F3/1000 -> 0.452 | H3: PAEX | I3: =VLOOKUP(H3,Segment1,2,FALSE) -> 0.3 | J3: =VLOOKUP(H3,Segment2,2,FALSE) -> 0.7 | K3: =VLOOKUP(H3,'Taux émission CO2e'!$A$5:$D$16,4,FALSE) -> 0.16 | L3: =IFERROR(I3*K3*G3*S3,"0") -> 11.02543 | M3: =VLOOKUP(H3,'Taux émission CO2e'!$A$20:$D$31,4,FALSE) -> 0.0674 | N3: =IFERROR(J3*M3*G3*S3,"0") -> 10.837079 | O3: =L3+N3 -> 21.862509 | P3: 220 | Q3: 67000 STRASBOURG | R3: 91100VILLABE | S3: 508.178
A4: 44201 | B4: =TEXT(A4,"mmmm") -> janvier | C4: =TEXT(A4,"aaaa") -> 2021 | D4: =B4&C4 -> janvier2021 | E4: 1308432 | F4: 249 | G4: =F4/1000 -> 0.249 | H4: PAEX | I4: =VLOOKUP(H4,Segment1,2,FALSE) -> 0.3 | J4: =VLOOKUP(H4,Segment2,2,FALSE) -> 0.7 | K4: =VLOOKUP(H4,'Taux émission CO2e'!$A$5:$D$16,4,FALSE) -> 0.16 | L4: =IFERROR(I4*K4*G4*S4,"0") -> 5.9988642 | M4: =VLOOKUP(H4,'Taux émission CO2e'!$A$20:$D$31,4,FALSE) -> 0.0674 | N4: =IFERROR(J4*M4*G4*S4,"0") -> 5.8963836 | O4: =L4+N4 -> 11.895248 | P4: 220 | Q4: 93120 COURNEUVE/LA | R4: 67100STRASBOURG | S4: 501.913
A5: 44201 | B5: =TEXT(A5,"mmmm") -> janvier | C5: =TEXT(A5,"aaaa") -> 2021 | D5: =B5&C5 -> janvier2021 | E5: 1309250 | F5: 500 | G5: =F5/1000 -> 0.5 | H5: PAEX | I5: =VLOOKUP(H5,Segment1,2,FALSE) -> 0.3 | J5: =VLOOKUP(H5,Segment2,2,FALSE) -> 0.7 | K5: =VLOOKUP(H5,'Taux émission CO2e'!$A$5:$D$16,4,FALSE) -> 0.16 | L5: =IFERROR(I5*K5*G5*S5,"0") -> 17.77068 | M5: =VLOOKUP(H5,'Taux émission CO2e'!$A$20:$D$31,4,FALSE) -> 0.0674 | N5: =IFERROR(J5*M5*G5*S5,"0") -> 17.467098 | O5: =L5+N5 -> 35.237778 | P5: 345 | Q5: 91100 VILLABE | R5: 13000MARSEILLE | S5: 740.445
A6: 44203 | B6: =TEXT(A6,"mmmm") -> janvier | C6: =TEXT(A6,"aaaa") -> 2021 | D6: =B6&C6 -> janvier2021 | E6: 1309627 | F6: 500 | G6: =F6/1000 -> 0.5 | H6: AFF | I6: =VLOOKUP(H6,Segment1,2,FALSE) -> 1 | J6: =VLOOKUP(H6,Segment2,2,FALSE) -> 0 | K6: =VLOOKUP(H6,'Taux émission CO2e'!$A$5:$D$16,4,FALSE) -> 0.0674 | L6: =IFERROR(I6*K6*G6*S6,"0") -> 1.8454457 | M6: =VLOOKUP(H6,'Taux émission CO2e'!$A$20:$D$31,4,FALSE) -> 0 | N6: =IFERROR(J6*M6*G6*S6,"0") -> 0 | O6: =L6+N6 -> 1.8454457 | P6: 152 | Q6: 93120 COURNEUVE/LA | R6: 91100VILLABE | S6: 54.761
A7: 44203 | B7: =TEXT(A7,"mmmm") -> janvier | C7: =TEXT(A7,"aaaa") -> 2021 | D7: =B7&C7 -> janvier2021 | E7: 1309609 | F7: 1250 | G7: =F7/1000 -> 1.25 | H7: AFF | I7: =VLOOKUP(H7,Segment1,2,FALSE) -> 1 | J7: =VLOOKUP(H7,Segment2,2,FALSE) -> 0 | K7: =VLOOKUP(H7,'Taux émission CO2e'!$A$5:$D$16,4,FALSE) -> 0.0674 | L7: =IFERROR(I7*K7*G7*S7,"0") -> 18.624305 | M7: =VLOOKUP(H7,'Taux émission CO2e'!$A$20:$D$31,4,FALSE) -> 0 | N7: =IFERROR(J7*M7*G7*S7,"0") -> 0 | O7: =L7+N7 -> 18.624305 | P7: 238 | Q7: 93120 COURNEUVE/LA | R7: 59100ROUBAIX | S7: 221.06
A8: 44204 | B8: =TEXT(A8,"mmmm") -> janvier | C8: =TEXT(A8,"aaaa") -> 2021 | D8: =B8&C8 -> janvier2021 | E8: 1310495 | F8: 80 | G8: =F8/1000 -> 0.08 | H8: POLE | I8: =VLOOKUP(H8,Segment1,2,FALSE) -> 0.3 | J8: =VLOOKUP(H8,Segment2,2,FALSE) -> 0.7 | K8: =VLOOKUP(H8,'Taux émission CO2e'!$A$5:$D$16,4,FALSE) -> 0.16 | L8: =IFERROR(I8*K8*G8*S8,"0") -> 0.98653824 | M8: =VLOOKUP(H8,'Taux émission CO2e'!$A$20:$D$31,4,FALSE) -> 0.0674 | N8: =IFERROR(J8*M8*G8*S8,"0") -> 0.96968488 | O8: =L8+N8 -> 1.9562231 | P8: 110 | Q8: 91100 VILLABE | R8: 8090CHARLEVILLE MEZ | S8: 256.911
A9: 44204 | B9: =TEXT(A9,"mmmm") -> janvier | C9: =TEXT(A9,"aaaa") -> 2021 | D9: =B9&C9 -> janvier2021 | E9: 1310502 | F9: 40 | G9: =F9/1000 -> 0.04 | H9: POLE | I9: =VLOOKUP(H9,Segment1,2,FALSE) -> 0.3 | J9: =VLOOKUP(H9,Segment2,2,FALSE) -> 0.7 | K9: =VLOOKUP(H9,'Taux émission CO2e'!$A$5:$D$16,4,FALSE) -> 0.16 | L9: =IFERROR(I9*K9*G9*S9,"0") -> 0.99033216 | M9: =VLOOKUP(H9,'Taux émission CO2e'!$A$20:$D$31,4,FALSE) -> 0.0674 | N9: =IFERROR(J9*M9*G9*S9,"0") -> 0.97341399 | O9: =L9+N9 -> 1.9637461 | P9: 140 | Q9: 91100 VILLABE | R9: 67100STRASBOURG | S9: 515.798
A10: 44204 | B10: =TEXT(A10,"mmmm") -> janvier | C10: =TEXT(A10,"aaaa") -> 2021 | D10: =B10&C10 -> janvier2021 | E10: 1310160 | F10: 1000 | G10: =F10/1000 -> 1 | H10: POLE | I10: =VLOOKUP(H10,Segment1,2,FALSE) -> 0.3 | J10: =VLOOKUP(H10,Segment2,2,FALSE) -> 0.7 | K10: =VLOOKUP(H10,'Taux émission CO2e'!$A$5:$D$16,4,FALSE) -> 0.16 | L10: =IFERROR(I10*K10*G10*S10,"0") -> 41.250624 | M10: =VLOOKUP(H10,'Taux émission CO2e'!$A$20:$D$31,4,FALSE) -> 0.0674 | N10: =IFERROR(J10*M10*G10*S10,"0") -> 40.545926 | O10: =L10+N10 -> 81.79655 | P10: 385 | Q10: 93120 COURNEUVE/LA | R10: 66000PERPIGNAN | S10: 859.388
A11: 44208 | B11: =TEXT(A11,"mmmm") -> janvier | C11: =TEXT(A11,"aaaa") -> 2021 | D11: =B11&C11 -> janvier2021 | E11: 1310601 | F11: 675 | G11: =F11/1000 -> 0.675 | H11: POLE | I11: =VLOOKUP(H11,Segment1,2,FALSE) -> 0.3 | J11: =VLOOKUP(H11,Segment2,2,FALSE) -> 0.7 | K11: =VLOOKUP(H11,'Taux émission CO2e'!$A$5:$D$16,4,FALSE) -> 0.16 | L11: =IFERROR(I11*K11*G11*S11,"0") -> 26.390513 | M11: =VLOOKUP(H11,'Taux émission CO2e'!$A$20:$D$31,4,FALSE) -> 0.0674 | N11: =IFERROR(J11*M11*G11*S11,"0") -> 25.939675 | O11: =L11+N11 -> 52.330188 | P11: 340 | Q11: 26750 ROMANS SUR ISER | R11: 59100ROUBAIX | S11: 814.522
A12: 44209 | B12: =TEXT(A12,"mmmm") -> janvier | C12: =TEXT(A12,"aaaa") -> 2021 | D12: =B12&C12 -> janvier2021 | E12: 1311894 | F12: 250 | G12: =F12/1000 -> 0.25 | H12: GV | I12: =VLOOKUP(H12,Segment1,2,FALSE) -> 1 | J12: =VLOOKUP(H12,Segment2,2,FALSE) -> 0 | K12: =VLOOKUP(H12,'Taux émission CO2e'!$A$5:$D$16,4,FALSE) -> 0.241 | L12: =IFERROR(I12*K12*G12*S12,"0") -> 3.252054 | M12: =VLOOKUP(H12,'Taux émission CO2e'!$A$20:$D$31,4,FALSE) -> 0 | N12: =IFERROR(J12*M12*G12*S12,"0") -> 0 | O12: =L12+N12 -> 3.252054 | P12: 98 | Q12: 91100 VILLABE | R12: 93120COURNEUVE/LA | S12: 53.976
A13: 44209 | B13: =TEXT(A13,"mmmm") -> janvier | C13: =TEXT(A13,"aaaa") -> 2021 | D13: =B13&C13 -> janvier2021 | E13: 1312188 | F13: 47 | G13: =F13/1000 -> 0.047 | H13: POLE | I13: =VLOOKUP(H13,Segment1,2,FALSE) -> 0.3 | J13: =VLOOKUP(H13,Segment2,2,FALSE) -> 0.7 | K13: =VLOOKUP(H13,'Taux émission CO2e'!$A$5:$D$16,4,FALSE) -> 0.16 | L13: =IFERROR(I13*K13*G13*S13,"0") -> 2.0065518 | M13: =VLOOKUP(H13,'Taux émission CO2e'!$A$20:$D$31,4,FALSE) -> 0.0674 | N13: =IFERROR(J13*M13*G13*S13,"0") -> 1.9722732 | O13: =L13+N13 -> 3.9788251 | P13: 153 | Q13: 91100 VILLABE | R13: 6700ST LAURENT DU VA | S13: 889.429
A14: 44211 | B14: =TEXT(A14,"mmmm") -> janvier | C14: =TEXT(A14,"aaaa") -> 2021 | D14: =B14&C14 -> janvier2021 | E14: 1312635 | F14: 500 | G14: =F14/1000 -> 0.5 | H14: PAEX | I14: =VLOOKUP(H14,Segment1,2,FALSE) -> 0.3 | J14: =VLOOKUP(H14,Segment2,2,FALSE) -> 0.7 | K14: =VLOOKUP(H14,'Taux émission CO2e'!$A$5:$D$16,4,FALSE) -> 0.16 | L14: =IFERROR(I14*K14*G14*S14,"0") -> 14.208336 | M14: =VLOOKUP(H14,'Taux émission CO2e'!$A$20:$D$31,4,FALSE) -> 0.0674 | N14: =IFERROR(J14*M14*G14*S14,"0") -> 13.96561 | O14: =L14+N14 -> 28.173946 | P14: 269 | Q14: 93120 COURNEUVE/LA | R14: 26750ROMANS SUR ISER | S14: 592.014
A15: 44214 | B15: =TEXT(A15,"mmmm") -> janvier | C15: =TEXT(A15,"aaaa") -> 2021 | D15: =B15&C15 -> janvier2021 | E15: 1 311 972 | F15: 300 | G15: =F15/1000 -> 0.3 | H15: NAV | I15: =VLOOKUP(H15,Segment1,2,FALSE) -> 1 | J15: =VLOOKUP(H15,Segment2,2,FALSE) -> 0 | K15: =VLOOKUP(H15,'Taux émission CO2e'!$A$5:$D$16,4,FALSE) -> 1.16 | L15: =IFERROR(I15*K15*G15*S15,"0") -> 0 | M15: =VLOOKUP(H15,'Taux émission CO2e'!$A$20:$D$31,4,FALSE) -> 0 | N15: =IFERROR(J15*M15*G15*S15,"0") -> 0 | O15: =L15+N15 -> 0 | P15: 2167 | Q15: 94440 MAROLLES EN BRI | R15: 97302CAYENNE | S15: 7.086,72
A16: 44214 | B16: =TEXT(A16,"mmmm") -> janvier | C16: =TEXT(A16,"aaaa") -> 2021 | D16: =B16&C16 -> janvier2021 | E16: 1311973 | F16: 300 | G16: =F16/1000 -> 0.3 | H16: PAEX | I16: =VLOOKUP(H16,Segment1,2,FALSE) -> 0.3 | J16: =VLOOKUP(H16,Segment2,2,FALSE) -> 0.7 | K16: =VLOOKUP(H16,'Taux émission CO2e'!$A$5:$D$16,4,FALSE) -> 0.16 | L16: =IFERROR(I16*K16*G16*S16,"0") -> 3.6129312 | M16: =VLOOKUP(H16,'Taux émission CO2e'!$A$20:$D$31,4,FALSE) -> 0.0674 | N16: =IFERROR(J16*M16*G16*S16,"0") -> 3.5512103 | O16: =L16+N16 -> 7.1641415 | P16: 140 | Q16: 94440 MAROLLES EN BRI | R16: 59100ROUBAIX | S16: 250.898
A17: 44214 | B17: =TEXT(A17,"mmmm") -> janvier | C17: =TEXT(A17,"aaaa") -> 2021 | D17: =B17&C17 -> janvier2021 | E17: 1312078 | F17: 200 | G17: =F17/1000 -> 0.2 | H17: PAEX | I17: =VLOOKUP(H17,Segment1,2,FALSE) -> 0.3 | J17: =VLOOKUP(H17,Segment2,2,FALSE) -> 0.7 | K17: =VLOOKUP(H17,'Taux émission CO2e'!$A$5:$D$16,4,FALSE) -> 0.16 | L17: =IFERROR(I17*K17*G17*S17,"0") -> 4.8785088 | M17: =VLOOKUP(H17,'Taux émission CO2e'!$A$20:$D$31,4,FALSE) -> 0.0674 | N17: =IFERROR(J17*M17*G17*S17,"0") -> 4.7951676 | O17: =L17+N17 -> 9.6736764 | P17: 175 | Q17: 67000 STRASBOURG | R17: 91100VILLABE | S17: 508.178
A18: 44214 | B18: =TEXT(A18,"mmmm") -> janvier | C18: =TEXT(A18,"aaaa") -> 2021 | D18: =B18&C18 -> janvier2021 | E18: 1312950 | F18: 300 | G18: =F18/1000 -> 0.3 | H18: PAEX | I18: =VLOOKUP(H18,Segment1,2,FALSE) -> 0.3 | J18: =VLOOKUP(H18,Segment2,2,FALSE) -> 0.7 | K18: =VLOOKUP(H18,'Taux émission CO2e'!$A$5:$D$16,4,FALSE) -> 0.16 | L18: =IFERROR(I18*K18*G18*S18,"0") -> 4.7611152 | M18: =VLOOKUP(H18,'Taux émission CO2e'!$A$20:$D$31,4,FALSE) -> 0.0674 | N18: =IFERROR(J18*M18*G18*S18,"0") -> 4.6797795 | O18: =L18+N18 -> 9.4408947 | P18: 182 | Q18: 93120 COURNEUVE/LA | R18: 21300CHENOVE | S18: 330.633
A19: 44218 | B19: =TEXT(A19,"mmmm") -> janvier | C19: =TEXT(A19,"aaaa") -> 2021 | D19: =B19&C19 -> janvier2021 | E19: 1315534 | F19: 200 | G19: =F19/1000 -> 0.2 | H19: PAEX | I19: =VLOOKUP(H19,Segment1,2,FALSE) -> 0.3 | J19: =VLOOKUP(H19,Segment2,2,FALSE) -> 0.7 | K19: =VLOOKUP(H19,'Taux émission CO2e'!$A$5:$D$16,4,FALSE) -> 0.16 | L19: =IFERROR(I19*K19*G19*S19,"0") -> 2.5551936 | M19: =VLOOKUP(H19,'Taux émission CO2e'!$A$20:$D$31,4,FALSE) -> 0.0674 | N19: =IFERROR(J19*M19*G19*S19,"0") -> 2.5115424 | O19: =L19+N19 -> 5.066736 | P19: 92 | Q19: 91100 VILLABE | R19: 59100ROUBAIX | S19: 266.166
A20: 44218 | B20: =TEXT(A20,"mmmm") -> janvier | C20: =TEXT(A20,"aaaa") -> 2021 | D20: =B20&C20 -> janvier2021 | E20: 1315539 | F20: 200 | G20: =F20/1000 -> 0.2 | H20: PAEX | I20: =VLOOKUP(H20,Segment1,2,FALSE) -> 0.3 | J20: =VLOOKUP(H20,Segment2,2,FALSE) -> 0.7 | K20: =VLOOKUP(H20,'Taux émission CO2e'!$A$5:$D$16,4,FALSE) -> 0.16 | L20: =IFERROR(I20*K20*G20*S20,"0") -> 2.549232 | M20: =VLOOKUP(H20,'Taux émission CO2e'!$A$20:$D$31,4,FALSE) -> 0.0674 | N20: =IFERROR(J20*M20*G20*S20,"0") -> 2.5056826 | O20: =L20+N20 -> 5.0549146 | P20: 92 | Q20: 91100 VILLABE | R20: 59200TOURCOING | S20: 265.545
A21: 44218 | B21: =TEXT(A21,"mmmm") -> janvier | C21: =TEXT(A21,"aaaa") -> 2021 | D21: =B21&C21 -> janvier2021 | E21: 1314972 | F21: 250 | G21: =F21/1000 -> 0.25 | H21: PAEX | I21: =VLOOKUP(H21,Segment1,2,FALSE) -> 0.3 | J21: =VLOOKUP(H21,Segment2,2,FALSE) -> 0.7 | K21: =VLOOKUP(H21,'Taux émission CO2e'!$A$5:$D$16,4,FALSE) -> 0.16 | L21: =IFERROR(I21*K21*G21*S21,"0") -> 0.999864 | M21: =VLOOKUP(H21,'Taux émission CO2e'!$A$20:$D$31,4,FALSE) -> 0.0674 | N21: =IFERROR(J21*M21*G21*S21,"0") -> 0.98278299 | O21: =L21+N21 -> 1.982647 | P21: 100 | Q21: 93120 COURNEUVE/LA | R21: 60000BEAUVAIS | S21: 83.322
A22: 44218 | B22: =TEXT(A22,"mmmm") -> janvier | C22: =TEXT(A22,"aaaa") -> 2021 | D22: =B22&C22 -> janvier2021 | E22: 1315161 | F22: 250 | G22: =F22/1000 -> 0.25 | H22: PAEX | I22: =VLOOKUP(H22,Segment1,2,FALSE) -> 0.3 | J22: =VLOOKUP(H22,Segment2,2,FALSE) -> 0.7 | K22: =VLOOKUP(H22,'Taux émission CO2e'!$A$5:$D$16,4,FALSE) -> 0.16 | L22: =IFERROR(I22*K22*G22*S22,"0") -> 6.022956 | M22: =VLOOKUP(H22,'Taux émission CO2e'!$A$20:$D$31,4,FALSE) -> 0.0674 | N22: =IFERROR(J22*M22*G22*S22,"0") -> 5.9200638 | O22: =L22+N22 -> 11.94302 | P22: 220 | Q22: 93120 COURNEUVE/LA | R22: 67100STRASBOURG | S22: 501.913
A23: 44218 | B23: =TEXT(A23,"mmmm") -> janvier | C23: =TEXT(A23,"aaaa") -> 2021 | D23: =B23&C23 -> janvier2021 | E23: 1314879 | F23: 200 | G23: =F23/1000 -> 0.2 | H23: AFF | I23: =VLOOKUP(H23,Segment1,2,FALSE) -> 1 | J23: =VLOOKUP(H23,Segment2,2,FALSE) -> 0 | K23: =VLOOKUP(H23,'Taux émission CO2e'!$A$5:$D$16,4,FALSE) -> 0.0674 | L23: =IFERROR(I23*K23*G23*S23,"0") -> 3.5879177 | M23: =VLOOKUP(H23,'Taux émission CO2e'!$A$20:$D$31,4,FALSE) -> 0 | N23: =IFERROR(J23*M23*G23*S23,"0") -> 0 | O23: =L23+N23 -> 3.5879177 | P23: 600 | Q23: 91100 VILLABE | R23: 59100ROUBAIX | S23: 266.166
A24: 44222 | B24: =TEXT(A24,"mmmm") -> janvier | C24: =TEXT(A24,"aaaa") -> 2021 | D24: =B24&C24 -> janvier2021 | E24: 1315693 | F24: 500 | G24: =F24/1000 -> 0.5 | H24: GV | I24: =VLOOKUP(H24,Segment1,2,FALSE) -> 1 | J24: =VLOOKUP(H24,Segment2,2,FALSE) -> 0 | K24: =VLOOKUP(H24,'Taux émission CO2e'!$A$5:$D$16,4,FALSE) -> 0.241 | L24: =IFERROR(I24*K24*G24*S24,"0") -> 6.5987005 | M24: =VLOOKUP(H24,'Taux émission CO2e'!$A$20:$D$31,4,FALSE) -> 0 | N24: =IFERROR(J24*M24*G24*S24,"0") -> 0 | O24: =L24+N24 -> 6.5987005 | P24: 123 | Q24: 93120 COURNEUVE/LA | R24: 91100VILLABE | S24: 54.761
A25: 44222 | B25: =TEXT(A25,"mmmm") -> janvier | C25: =TEXT(A25,"aaaa") -> 2021 | D25: =B25&C25 -> janvier2021 | E25: 1315964 | F25: 1000 | G25: =F25/1000 -> 1 | H25: POLE | I25: =VLOOKUP(H25,Segment1,2,FALSE) -> 0.3 | J25: =VLOOKUP(H25,Segment2,2,FALSE) -> 0.7 | K25: =VLOOKUP(H25,'Taux émission CO2e'!$A$5:$D$16,4,FALSE) -> 0.16 | L25: =IFERROR(I25*K25*G25*S25,"0") -> 28.416672 | M25: =VLOOKUP(H25,'Taux émission CO2e'!$A$20:$D$31,4,FALSE) -> 0.0674 | N25: =IFERROR(J25*M25*G25*S25,"0") -> 27.931221 | O25: =L25+N25 -> 56.347893 | P25: 269 | Q25: 93120 COURNEUVE/LA | R25: 26750ROMANS SUR ISER | S25: 592.014
A26: 44223 | B26: =TEXT(A26,"mmmm") -> janvier | C26: =TEXT(A26,"aaaa") -> 2021 | D26: =B26&C26 -> janvier2021 | E26: 1316628 | F26: 225 | G26: =F26/1000 -> 0.225 | H26: PAEX | I26: =VLOOKUP(H26,Segment1,2,FALSE) -> 0.3 | J26: =VLOOKUP(H26,Segment2,2,FALSE) -> 0.7 | K26: =VLOOKUP(H26,'Taux émission CO2e'!$A$5:$D$16,4,FALSE) -> 0.16 | L26: =IFERROR(I26*K26*G26*S26,"0") -> 10.656965 | M26: =VLOOKUP(H26,'Taux émission CO2e'!$A$20:$D$31,4,FALSE) -> 0.0674 | N26: =IFERROR(J26*M26*G26*S26,"0") -> 10.474908 | O26: =L26+N26 -> 21.131873 | P26: 175 | Q26: 40300 PEYREHORADE | R26: 59100ROUBAIX | S26: 986.756
A27: 44223 | B27: =TEXT(A27,"mmmm") -> janvier | C27: =TEXT(A27,"aaaa") -> 2021 | D27: =B27&C27 -> janvier2021 | E27: 1316391 | F27: 450 | G27: =F27/1000 -> 0.45 | H27: POLE | I27: =VLOOKUP(H27,Segment1,2,FALSE) -> 0.3 | J27: =VLOOKUP(H27,Segment2,2,FALSE) -> 0.7 | K27: =VLOOKUP(H27,'Taux émission CO2e'!$A$5:$D$16,4,FALSE) -> 0.16 | L27: =IFERROR(I27*K27*G27*S27,"0") -> 17.593675 | M27: =VLOOKUP(H27,'Taux émission CO2e'!$A$20:$D$31,4,FALSE) -> 0.0674 | N27: =IFERROR(J27*M27*G27*S27,"0") -> 17.293117 | O27: =L27+N27 -> 34.886792 | P27: 288 | Q27: 26750 ROMANS SUR ISER | R27: 59100ROUBAIX | S27: 814.522
... A96: 44267 | B96: =TEXT(A96,"mmmm") -> mars | C96: =TEXT(A96,"aaaa") -> 2021 | D96: =B96&C96 -> mars2021 | E96: 1336645 | F96: 200 | G96: =F96/1000 -> 0.2 | H96: POLE | I96: =VLOOKUP(H96,Segment1,2,FALSE) -> 0.3 | J96: =VLOOKUP(H96,Segment2,2,FALSE) -> 0.7 | K96: =VLOOKUP(H96,'Taux émission CO2e'!$A$5:$D$16,4,FALSE) -> 0.16 | L96: =IFERROR(I96*K96*G96*S96,"0") -> 2.670192 | M96: =VLOOKUP(H96,'Taux émission CO2e'!$A$20:$D$31,4,FALSE) -> 0.0674 | N96: =IFERROR(J96*M96*G96*S96,"0") -> 2.6245762 | O96: =L96+N96 -> 5.2947682 | P96: 90 | Q96: 21300 CHENOVE | R96: 91100VILLABE | S96: 278.145
A97: 44267 | B97: =TEXT(A97,"mmmm") -> mars | C97: =TEXT(A97,"aaaa") -> 2021 | D97: =B97&C97 -> mars2021 | E97: 1 336 708 | F97: 250 | G97: =F97/1000 -> 0.25 | H97: NAV | I97: =VLOOKUP(H97,Segment1,2,FALSE) -> 1 | J97: =VLOOKUP(H97,Segment2,2,FALSE) -> 0 | K97: =VLOOKUP(H97,'Taux émission CO2e'!$A$5:$D$16,4,FALSE) -> 1.16 | L97: =IFERROR(I97*K97*G97*S97,"0") -> 0 | M97: =VLOOKUP(H97,'Taux émission CO2e'!$A$20:$D$31,4,FALSE) -> 0 | N97: =IFERROR(J97*M97*G97*S97,"0") -> 0 | O97: =L97+N97 -> 0 | P97: 2098.00 | Q97: 93120 COURNEUVE/LA | R97: 97217LES ANSES D'ARLET | S97: 6,871.60
A98: 44267 | B98: =TEXT(A98,"mmmm") -> mars | C98: =TEXT(A98,"aaaa") -> 2021 | D98: =B98&C98 -> mars2021 | E98: 1336709 | F98: 250 | G98: =F98/1000 -> 0.25 | H98: AFF | I98: =VLOOKUP(H98,Segment1,2,FALSE) -> 1 | J98: =VLOOKUP(H98,Segment2,2,FALSE) -> 0 | K98: =VLOOKUP(H98,'Taux émission CO2e'!$A$5:$D$16,4,FALSE) -> 0.0674 | L98: =IFERROR(I98*K98*G98*S98,"0") -> 0.64695575 | M98: =VLOOKUP(H98,'Taux émission CO2e'!$A$20:$D$31,4,FALSE) -> 0 | N98: =IFERROR(J98*M98*G98*S98,"0") -> 0 | O98: =L98+N98 -> 0.64695575 | P98: 98 | Q98: 93120 COURNEUVE/LA | R98: 94440MAROLLES EN BRI | S98: 38.395
A99: 44267 | B99: =TEXT(A99,"mmmm") -> mars | C99: =TEXT(A99,"aaaa") -> 2021 | D99: =B99&C99 -> mars2021 | E99: 1336568 | F99: 250 | G99: =F99/1000 -> 0.25 | H99: POLE | I99: =VLOOKUP(H99,Segment1,2,FALSE) -> 0.3 | J99: =VLOOKUP(H99,Segment2,2,FALSE) -> 0.7 | K99: =VLOOKUP(H99,'Taux émission CO2e'!$A$5:$D$16,4,FALSE) -> 0.16 | L99: =IFERROR(I99*K99*G99*S99,"0") -> 6.498312 | M99: =VLOOKUP(H99,'Taux émission CO2e'!$A$20:$D$31,4,FALSE) -> 0.0674 | N99: =IFERROR(J99*M99*G99*S99,"0") -> 6.3872992 | O99: =L99+N99 -> 12.885611 | P99: 115 | Q99: 26750 ROMANS SUR ISER | R99: 91100VILLABE | S99: 541.526
A100: 44270 | B100: =TEXT(A100,"mmmm") -> mars | C100: =TEXT(A100,"aaaa") -> 2021 | D100: =B100&C100 -> mars2021 | E100: 1337321 | F100: 90 | G100: =F100/1000 -> 0.09 | H100: PAEX | I100: =VLOOKUP(H100,Segment1,2,FALSE) -> 0.3 | J100: =VLOOKUP(H100,Segment2,2,FALSE) -> 0.7 | K100: =VLOOKUP(H100,'Taux émission CO2e'!$A$5:$D$16,4,FALSE) -> 0.16 | L100: =IFERROR(I100*K100*G100*S100,"0") -> 2.2282474 | M100: =VLOOKUP(H100,'Taux émission CO2e'!$A$20:$D$31,4,FALSE) -> 0.0674 | N100: =IFERROR(J100*M100*G100*S100,"0") -> 2.1901815 | O100: =L100+N100 -> 4.4184288 | P100: 140 | Q100: 91100 VILLABE | R100: 67100STRASBOURG | S100: 515.798
A101: 44271 | B101: =TEXT(A101,"mmmm") -> mars | C101: =TEXT(A101,"aaaa") -> 2021 | D101: =B101&C101 -> mars2021 | E101: 1337756 | F101: 120 | G101: =F101/1000 -> 0.12 | H101: PAEX | I101: =VLOOKUP(H101,Segment1,2,FALSE) -> 0.3 | J101: =VLOOKUP(H101,Segment2,2,FALSE) -> 0.7 | K101: =VLOOKUP(H101,'Taux émission CO2e'!$A$5:$D$16,4,FALSE) -> 0.16 | L101: =IFERROR(I101*K101*G101*S101,"0") -> 1.443335 | M101: =VLOOKUP(H101,'Taux émission CO2e'!$A$20:$D$31,4,FALSE) -> 0.0674 | N101: =IFERROR(J101*M101*G101*S101,"0") -> 1.4186781 | O101: =L101+N101 -> 2.8620131 | P101: 92 | Q101: 91100 VILLABE | R101: 59243QUAROUBLE | S101: 250.579
A102: 44271 | B102: =TEXT(A102,"mmmm") -> mars | C102: =TEXT(A102,"aaaa") -> 2021 | D102: =B102&C102 -> mars2021 | E102: 1337765 | F102: 100 | G102: =F102/1000 -> 0.1 | H102: PAEX | I102: =VLOOKUP(H102,Segment1,2,FALSE) -> 0.3 | J102: =VLOOKUP(H102,Segment2,2,FALSE) -> 0.7 | K102: =VLOOKUP(H102,'Taux émission CO2e'!$A$5:$D$16,4,FALSE) -> 0.16 | L102: =IFERROR(I102*K102*G102*S102,"0") -> 1.22004 | M102: =VLOOKUP(H102,'Taux émission CO2e'!$A$20:$D$31,4,FALSE) -> 0.0674 | N102: =IFERROR(J102*M102*G102*S102,"0") -> 1.1991977 | O102: =L102+N102 -> 2.4192377 | P102: 95 | Q102: 91100 VILLABE | R102: 59800LILLE | S102: 254.175
A103: 44271 | B103: =TEXT(A103,"mmmm") -> mars | C103: =TEXT(A103,"aaaa") -> 2021 | D103: =B103&C103 -> mars2021 | E103: 1337958 | F103: 250 | G103: =F103/1000 -> 0.25 | H103: GV | I103: =VLOOKUP(H103,Segment1,2,FALSE) -> 1 | J103: =VLOOKUP(H103,Segment2,2,FALSE) -> 0 | K103: =VLOOKUP(H103,'Taux émission CO2e'!$A$5:$D$16,4,FALSE) -> 0.241 | L103: =IFERROR(I103*K103*G103*S103,"0") -> 3.252054 | M103: =VLOOKUP(H103,'Taux émission CO2e'!$A$20:$D$31,4,FALSE) -> 0 | N103: =IFERROR(J103*M103*G103*S103,"0") -> 0 | O103: =L103+N103 -> 3.252054 | P103: 98 | Q103: 91100 VILLABE | R103: 93120COURNEUVE/LA | S103: 53.976
A104: 44271 | B104: =TEXT(A104,"mmmm") -> mars | C104: =TEXT(A104,"aaaa") -> 2021 | D104: =B104&C104 -> mars2021 | E104: 1338078 | F104: 160 | G104: =F104/1000 -> 0.16 | H104: PAEX | I104: =VLOOKUP(H104,Segment1,2,FALSE) -> 0.3 | J104: =VLOOKUP(H104,Segment2,2,FALSE) -> 0.7 | K104: =VLOOKUP(H104,'Taux émission CO2e'!$A$5:$D$16,4,FALSE) -> 0.16 | L104: =IFERROR(I104*K104*G104*S104,"0") -> 2.1557606 | M104: =VLOOKUP(H104,'Taux émission CO2e'!$A$20:$D$31,4,FALSE) -> 0.0674 | N104: =IFERROR(J104*M104*G104*S104,"0") -> 2.1189331 | O104: =L104+N104 -> 4.2746937 | P104: 100 | Q104: 91100 VILLABE | R104: 62780CUCQ | S104: 280.698
A105: 44271 | B105: =TEXT(A105,"mmmm") -> mars | C105: =TEXT(A105,"aaaa") -> 2021 | D105: =B105&C105 -> mars2021 | E105: 1337761 | F105: 100 | G105: =F105/1000 -> 0.1 | H105: PAEX | I105: =VLOOKUP(H105,Segment1,2,FALSE) -> 0.3 | J105: =VLOOKUP(H105,Segment2,2,FALSE) -> 0.7 | K105: =VLOOKUP(H105,'Taux émission CO2e'!$A$5:$D$16,4,FALSE) -> 0.16 | L105: =IFERROR(I105*K105*G105*S105,"0") -> 1.2331728 | M105: =VLOOKUP(H105,'Taux émission CO2e'!$A$20:$D$31,4,FALSE) -> 0.0674 | N105: =IFERROR(J105*M105*G105*S105,"0") -> 1.2121061 | O105: =L105+N105 -> 2.4452789 | P105: 110 | Q105: 91100 VILLABE | R105: 8090CHARLEVILLE MEZ | S105: 256.911
A106: 44271 | B106: =TEXT(A106,"mmmm") -> mars | C106: =TEXT(A106,"aaaa") -> 2021 | D106: =B106&C106 -> mars2021 | E106: 1337179 | F106: 200 | G106: =F106/1000 -> 0.2 | H106: POLE | I106: =VLOOKUP(H106,Segment1,2,FALSE) -> 0.3 | J106: =VLOOKUP(H106,Segment2,2,FALSE) -> 0.7 | K106: =VLOOKUP(H106,'Taux émission CO2e'!$A$5:$D$16,4,FALSE) -> 0.16 | L106: =IFERROR(I106*K106*G106*S106,"0") -> 2.4026688 | M106: =VLOOKUP(H106,'Taux émission CO2e'!$A$20:$D$31,4,FALSE) -> 0.0674 | N106: =IFERROR(J106*M106*G106*S106,"0") -> 2.3616232 | O106: =L106+N106 -> 4.764292 | P106: 115 | Q106: 59810 LESQUIN | R106: 91100VILLABE | S106: 250.278
A107: 44272 | B107: =TEXT(A107,"mmmm") -> mars | C107: =TEXT(A107,"aaaa") -> 2021 | D107: =B107&C107 -> mars2021 | E107: 1337601 | F107: 200 | G107: =F107/1000 -> 0.2 | H107: POLE | I107: =VLOOKUP(H107,Segment1,2,FALSE) -> 0.3 | J107: =VLOOKUP(H107,Segment2,2,FALSE) -> 0.7 | K107: =VLOOKUP(H107,'Taux émission CO2e'!$A$5:$D$16,4,FALSE) -> 0.16 | L107: =IFERROR(I107*K107*G107*S107,"0") -> 2.4184224 | M107: =VLOOKUP(H107,'Taux émission CO2e'!$A$20:$D$31,4,FALSE) -> 0.0674 | N107: =IFERROR(J107*M107*G107*S107,"0") -> 2.3771077 | O107: =L107+N107 -> 4.7955301 | P107: 115 | Q107: 59243 QUAROUBLE | R107: 91100VILLABE | S107: 251.919
A108: 44273 | B108: =TEXT(A108,"mmmm") -> mars | C108: =TEXT(A108,"aaaa") -> 2021 | D108: =B108&C108 -> mars2021 | E108: 1338946 | F108: 200 | G108: =F108/1000 -> 0.2 | H108: PAEX | I108: =VLOOKUP(H108,Segment1,2,FALSE) -> 0.3 | J108: =VLOOKUP(H108,Segment2,2,FALSE) -> 0.7 | K108: =VLOOKUP(H108,'Taux émission CO2e'!$A$5:$D$16,4,FALSE) -> 0.16 | L108: =IFERROR(I108*K108*G108*S108,"0") -> 2.5551936 | M108: =VLOOKUP(H108,'Taux émission CO2e'!$A$20:$D$31,4,FALSE) -> 0.0674 | N108: =IFERROR(J108*M108*G108*S108,"0") -> 2.5115424 | O108: =L108+N108 -> 5.066736 | P108: 92 | Q108: 91100 VILLABE | R108: 59100ROUBAIX | S108: 266.166
...

Sheet Indicateurs transport
S1: Emetteur : | T1: JEAN-PHILIPPE Bénédy
D2: TABLEAU DE BORD INDICATEURS TRANSPORT - CUMUL 9 MOIS | S2: Date réalisation : | T2: 45454
E4: 1. Nombre ordres de transport (OT) | J4: 2. Poids transporté (Kg) | O4: 3. Poids moyen (Kg/OT) | T4: 4. KM réalisés (km) | Y4: 5. KM moyen (KM/OT)
E5: 2021 | F5: 2022 | G5: %A/A-1 | J5: 2021 | K5: 2022 | L5: %A/A-1 | O5: 2021 | P5: 2022 | Q5: %A/A-1 | T5: 2021 | U5: 2022 | V5: %A/A-1 | Y5: 2021 | Z5: 2022 | AA5: %A/A-1
B6: =D6&$E$5 -> janvier2021 | C6: =D6&$F$5 -> janvier2022 | D6: janvier | E6: =COUNTIFS(Import!$D$1:$D$1482,B6) -> 31 | F6: =COUNTIFS(Import!$D$1:$D$1482,C6) -> 32 | G6: =IF(F6=0,,F6/E6-1) -> 0.032258065 | I6: janvier | J6: =SUMIFS(Import!F:F,Import!D:D,'Indicateurs transport'!B6) -> 18053 | K6: =SUMIFS(Import!F:F,Import!D:D,'Indicateurs transport'!C6) -> 10517 | L6: =IF(K6=0,,K6/J6-1) -> -0.41743755 | N6: janvier | O6: =IFERROR(J6/E6, 0) -> 582.35484 | P6: =IFERROR(K6/F6, 0) -> 328.65625 | Q6: =IF(P6=0,,P6/O6-1) -> -0.43564262 | S6: janvier | T6: =SUMIFS(Import!$S$2:$S$1482,Import!$D$2:$D$1482,'Indicateurs transport'!B6) -> 12548.985 | U6: =SUMIFS(Import!$S$2:$S$1482,Import!$D$2:$D$1482,'Indicateurs transport'!C6) -> 11522.19 | V6: =IF(U6=0,,U6/T6-1) -> -0.081822952 | X6: janvier | Y6: =IF(T6=0,,T6/E6) -> 404.80597 | Z6: =IF(U6=0,,U6/F6) -> 360.06844 | AA6: =IF(Z6=0,,Z6/Y6-1) -> -0.11051598
B7: =D7&$E$5 -> février2021 | C7: =D7&$F$5 -> février2022 | D7: février | E7: =COUNTIFS(Import!$D$1:$D$1482,B7) -> 42 | F7: =COUNTIFS(Import!$D$1:$D$1482,C7) -> 69 | G7: =IF(F7=0,,F7/E7-1) -> 0.64285714 | I7: février | J7: =SUMIFS(Import!F:F,Import!D:D,'Indicateurs transport'!B7) -> 12198 | K7: =SUMIFS(Import!F:F,Import!D:D,'Indicateurs transport'!C7) -> 17805 | L7: =IF(K7=0,,K7/J7-1) -> 0.45966552 | N7: février | O7: =IFERROR(J7/E7, 0) -> 290.42857 | P7: =IFERROR(K7/F7, 0) -> 258.04348 | Q7: =IF(P7=0,,P7/O7-1) -> -0.11150794 | S7: février | T7: =SUMIFS(Import!$S$2:$S$1482,Import!$D$2:$D$1482,'Indicateurs transport'!B7) -> 16191.553 | U7: =SUMIFS(Import!$S$2:$S$1482,Import!$D$2:$D$1482,'Indicateurs transport'!C7) -> 25546.339 | V7: =IF(U7=0,,U7/T7-1) -> 0.57775718 | X7: février | Y7: =IF(T7=0,,T7/E7) -> 385.51317 | Z7: =IF(U7=0,,U7/F7) -> 370.2368 | AA7: =IF(Z7=0,,Z7/Y7-1) -> -0.039626064
B8: =D8&$E$5 -> mars2021 | C8: =D8&$F$5 -> mars2022 | D8: mars | E8: =COUNTIFS(Import!$D$1:$D$1482,B8) -> 64 | F8: =COUNTIFS(Import!$D$1:$D$1482,C8) -> 141 | G8: =IF(F8=0,,F8/E8-1) -> 1.203125 | I8: mars | J8: =SUMIFS(Import!F:F,Import!D:D,'Indicateurs transport'!B8) -> 17800 | K8: =SUMIFS(Import!F:F,Import!D:D,'Indicateurs transport'!C8) -> 39619 | L8: =IF(K8=0,,K8/J8-1) -> 1.2257865 | N8: mars | O8: =IFERROR(J8/E8, 0) -> 278.125 | P8: =IFERROR(K8/F8, 0) -> 280.98582 | Q8: =IF(P8=0,,P8/O8-1) -> 0.010286079 | S8: mars | T8: =SUMIFS(Import!$S$2:$S$1482,Import!$D$2:$D$1482,'Indicateurs transport'!B8) -> 20002.071 | U8: =SUMIFS(Import!$S$2:$S$1482,Import!$D$2:$D$1482,'Indicateurs transport'!C8) -> 51154.93 | V8: =IF(U8=0,,U8/T8-1) -> 1.5574817 | X8: mars | Y8: =IF(T8=0,,T8/E8) -> 312.53236 | Z8: =IF(U8=0,,U8/F8) -> 362.80092 | AA8: =IF(Z8=0,,Z8/Y8-1) -> 0.16084275
B9: =D9&$E$5 -> avril2021 | C9: =D9&$F$5 -> avril2022 | D9: avril | E9: =COUNTIFS(Import!$D$1:$D$1482,B9) -> 52 | F9: =COUNTIFS(Import!$D$1:$D$1482,C9) -> 128 | G9: =IF(F9=0,,F9/E9-1) -> 1.4615385 | I9: avril | J9: =SUMIFS(Import!F:F,Import!D:D,'Indicateurs transport'!B9) -> 14855 | K9: =SUMIFS(Import!F:F,Import!D:D,'Indicateurs transport'!C9) -> 45889 | L9: =IF(K9=0,,K9/J9-1) -> 2.0891282 | N9: avril | O9: =IFERROR(J9/E9, 0) -> 285.67308 | P9: =IFERROR(K9/F9, 0) -> 358.50781 | Q9: =IF(P9=0,,P9/O9-1) -> 0.25495835 | S9: avril | T9: =SUMIFS(Import!$S$2:$S$1482,Import!$D$2:$D$1482,'Indicateurs transport'!B9) -> 17638.505 | U9: =SUMIFS(Import!$S$2:$S$1482,Import!$D$2:$D$1482,'Indicateurs transport'!C9) -> 43743.548 | V9: =IF(U9=0,,U9/T9-1) -> 1.4800032 | X9: avril | Y9: =IF(T9=0,,T9/E9) -> 339.20202 | Z9: =IF(U9=0,,U9/F9) -> 341.74647 | AA9: =IF(Z9=0,,Z9/Y9-1) -> 0.0075012806
B10: =D10&$E$5 -> mai2021 | C10: =D10&$F$5 -> mai2022 | D10: mai | E10: =COUNTIFS(Import!$D$1:$D$1482,B10) -> 54 | F10: =COUNTIFS(Import!$D$1:$D$1482,C10) -> 145 | G10: =IF(F10=0,,F10/E10-1) -> 1.6851852 | I10: mai | J10: =SUMIFS(Import!F:F,Import!D:D,'Indicateurs transport'!B10) -> 15055 | K10: =SUMIFS(Import!F:F,Import!D:D,'Indicateurs transport'!C10) -> 47442 | L10: =IF(K10=0,,K10/J10-1) -> 2.1512454 | N10: mai | O10: =IFERROR(J10/E10, 0) -> 278.7963 | P10: =IFERROR(K10/F10, 0) -> 327.18621 | Q10: =IF(P10=0,,P10/O10-1) -> 0.17356726 | S10: mai | T10: =SUMIFS(Import!$S$2:$S$1482,Import!$D$2:$D$1482,'Indicateurs transport'!B10) -> 16365.549 | U10: =SUMIFS(Import!$S$2:$S$1482,Import!$D$2:$D$1482,'Indicateurs transport'!C10) -> 50423.278 | V10: =IF(U10=0,,U10/T10-1) -> 2.0810624 | X10: mai | Y10: =IF(T10=0,,T10/E10) -> 303.06572 | Z10: =IF(U10=0,,U10/F10) -> 347.74674 | AA10: =IF(Z10=0,,Z10/Y10-1) -> 0.14743014
B11: =D11&$E$5 -> juin2021 | C11: =D11&$F$5 -> juin2022 | D11: juin | E11: =COUNTIFS(Import!$D$1:$D$1482,B11) -> 59 | F11: =COUNTIFS(Import!$D$1:$D$1482,C11) -> 167 | G11: =IF(F11=0,,F11/E11-1) -> 1.8305085 | I11: juin | J11: =SUMIFS(Import!F:F,Import!D:D,'Indicateurs transport'!B11) -> 19180 | K11: =SUMIFS(Import!F:F,Import!D:D,'Indicateurs transport'!C11) -> 54949 | L11: =IF(K11=0,,K11/J11-1) -> 1.8649114 | N11: juin | O11: =IFERROR(J11/E11, 0) -> 325.08475 | P11: =IFERROR(K11/F11, 0) -> 329.03593 | Q11: =IF(P11=0,,P11/O11-1) -> 0.012154315 | S11: juin | T11: =SUMIFS(Import!$S$2:$S$1482,Import!$D$2:$D$1482,'Indicateurs transport'!B11) -> 17451.166 | U11: =SUMIFS(Import!$S$2:$S$1482,Import!$D$2:$D$1482,'Indicateurs transport'!C11) -> 61226.338 | V11: =IF(U11=0,,U11/T11-1) -> 2.5084382 | X11: juin | Y11: =IF(T11=0,,T11/E11) -> 295.78247 | Z11: =IF(U11=0,,U11/F11) -> 366.62478 | AA11: =IF(Z11=0,,Z11/Y11-1) -> 0.23950812
B12: =D12&$E$5 -> juillet2021 | C12: =D12&$F$5 -> juillet2022 | D12: juillet | E12: =COUNTIFS(Import!$D$1:$D$1482,B12) -> 50 | F12: =COUNTIFS(Import!$D$1:$D$1482,C12) -> 118 | G12: =IF(F12=0,,F12/E12-1) -> 1.36 | I12: juillet | J12: =SUMIFS(Import!F:F,Import!D:D,'Indicateurs transport'!B12) -> 14840 | K12: =SUMIFS(Import!F:F,Import!D:D,'Indicateurs transport'!C12) -> 34775 | L12: =IF(K12=0,,K12/J12-1) -> 1.3433288 | N12: juillet | O12: =IFERROR(J12/E12, 0) -> 296.8 | P12: =IFERROR(K12/F12, 0) -> 294.70339 | Q12: =IF(P12=0,,P12/O12-1) -> -0.0070640504 | S12: juillet | T12: =SUMIFS(Import!$S$2:$S$1482,Import!$D$2:$D$1482,'Indicateurs transport'!B12) -> 17036.291 | U12: =SUMIFS(Import!$S$2:$S$1482,Import!$D$2:$D$1482,'Indicateurs transport'!C12) -> 45173.56 | V12: =IF(U12=0,,U12/T12-1) -> 1.6516077 | X12: juillet | Y12: =IF(T12=0,,T12/E12) -> 340.72582 | Z12: =IF(U12=0,,U12/F12) -> 382.82678 | AA12: =IF(Z12=0,,Z12/Y12-1) -> 0.12356257
B13: =D13&$E$5 -> août2021 | C13: =D13&$F$5 -> août2022 | D13: août | E13: =COUNTIFS(Import!$D$1:$D$1482,B13) -> 55 | F13: =COUNTIFS(Import!$D$1:$D$1482,C13) -> 120 | G13: =IF(F13=0,,F13/E13-1) -> 1.1818182 | I13: aout | J13: =SUMIFS(Import!F:F,Import!D:D,'Indicateurs transport'!B13) -> 20230 | K13: =SUMIFS(Import!F:F,Import!D:D,'Indicateurs transport'!C13) -> 43452 | L13: =IF(K13=0,,K13/J13-1) -> 1.1478992 | N13: aout | O13: =IFERROR(J13/E13, 0) -> 367.81818 | P13: =IFERROR(K13/F13, 0) -> 362.1 | Q13: =IF(P13=0,,P13/O13-1) -> -0.015546218 | S13: aout | T13: =SUMIFS(Import!$S$2:$S$1482,Import!$D$2:$D$1482,'Indicateurs transport'!B13) -> 18325.828 | U13: =SUMIFS(Import!$S$2:$S$1482,Import!$D$2:$D$1482,'Indicateurs transport'!C13) -> 45922.895 | V13: =IF(U13=0,,U13/T13-1) -> 1.5059111 | X13: aout | Y13: =IF(T13=0,,T13/E13) -> 333.19687 | Z13: =IF(U13=0,,U13/F13) -> 382.69079 | AA13: =IF(Z13=0,,Z13/Y13-1) -> 0.14854257
B14: =D14&$E$5 -> septembre2021 | C14: =D14&$F$5 -> septembre2022 | D14: septembre | E14: =COUNTIFS(Import!$D$1:$D$1482,B14) -> 48 | F14: =COUNTIFS(Import!$D$1:$D$1482,C14) -> 106 | G14: =IF(F14=0,,F14/E14-1) -> 1.2083333 | I14: septembre | J14: =SUMIFS(Import!F:F,Import!D:D,'Indicateurs transport'!B14) -> 18325 | K14: =SUMIFS(Import!F:F,Import!D:D,'Indicateurs transport'!C14) -> 39204 | L14: =IF(K14=0,,K14/J14-1) -> 1.1393724 | N14: septembre | O14: =IFERROR(J14/E14, 0) -> 381.77083 | P14: =IFERROR(K14/F14, 0) -> 369.84906 | Q14: =IF(P14=0,,P14/O14-1) -> -0.031227573 | S14: septembre | T14: =SUMIFS(Import!$S$2:$S$1482,Import!$D$2:$D$1482,'Indicateurs transport'!B14) -> 14579.262 | U14: =SUMIFS(Import!$S$2:$S$1482,Import!$D$2:$D$1482,'Indicateurs transport'!C14) -> 39258.042 | V14: =IF(U14=0,,U14/T14-1) -> 1.6927318 | X14: septembre | Y14: =IF(T14=0,,T14/E14) -> 303.73462 | Z14: =IF(U14=0,,U14/F14) -> 370.35889 | AA14: =IF(Z14=0,,Z14/Y14-1) -> 0.21935024
B15: =D15&$E$5 -> octobre2021 | C15: =D15&$F$5 -> octobre2022 | D15: octobre | E15: =COUNTIFS(Import!$D$1:$D$1482,B15) -> 0 | F15: =COUNTIFS(Import!$D$1:$D$1482,C15) -> 0 | G15: =IF(F15=0,,F15/E15-1) -> 0 | I15: octobre | J15: =SUMIFS(Import!F:F,Import!D:D,'Indicateurs transport'!B15) -> 0 | K15: =SUMIFS(Import!F:F,Import!D:D,'Indicateurs transport'!C15) -> 0 | L15: =IF(K15=0,,K15/J15-1) -> 0 | N15: octobre | O15: =IFERROR(J15/E15, 0) -> 0 | P15: =IFERROR(K15/F15, 0) -> 0 | Q15: =IF(P15=0,,P15/O15-1) -> 0 | S15: octobre | T15: =SUMIFS(Import!$S$2:$S$1482,Import!$D$2:$D$1482,'Indicateurs transport'!B15) -> 0 | U15: =SUMIFS(Import!$S$2:$S$1482,Import!$D$2:$D$1482,'Indicateurs transport'!C15) -> 0 | V15: =IF(U15=0,,U15/T15-1) -> 0 | X15: octobre | Y15: =IF(T15=0,,T15/E15) -> 0 | Z15: =IF(U15=0,,U15/F15) -> 0 | AA15: =IF(Z15=0,,Z15/Y15-1) -> 0
B16: =D16&$E$5 -> novembre2021 | C16: =D16&$F$5 -> novembre2022 | D16: novembre | E16: =COUNTIFS(Import!$D$1:$D$1482,B16) -> 0 | F16: =COUNTIFS(Import!$D$1:$D$1482,C16) -> 0 | G16: =IF(F16=0,,F16/E16-1) -> 0 | I16: novembre | J16: =SUMIFS(Import!F:F,Import!D:D,'Indicateurs transport'!B16) -> 0 | K16: =SUMIFS(Import!F:F,Import!D:D,'Indicateurs transport'!C16) -> 0 | L16: =IF(K16=0,,K16/J16-1) -> 0 | N16: novembre | O16: =IFERROR(J16/E16, 0) -> 0 | P16: =IFERROR(K16/F16, 0) -> 0 | Q16: =IF(P16=0,,P16/O16-1) -> 0 | S16: novembre | T16: =SUMIFS(Import!$S$2:$S$1482,Import!$D$2:$D$1482,'Indicateurs transport'!B16) -> 0 | U16: =SUMIFS(Import!$S$2:$S$1482,Import!$D$2:$D$1482,'Indicateurs transport'!C16) -> 0 | V16: =IF(U16=0,,U16/T16-1) -> 0 | X16: novembre | Y16: =IF(T16=0,,T16/E16) -> 0 | Z16: =IF(U16=0,,U16/F16) -> 0 | AA16: =IF(Z16=0,,Z16/Y16-1) -> 0
B17: =D17&$E$5 -> décembre2021 | C17: =D17&$F$5 -> décembre2022 | D17: décembre | E17: =COUNTIFS(Import!$D$1:$D$1482,B17) -> 0 | F17: =COUNTIFS(Import!$D$1:$D$1482,C17) -> 0 | G17: =IF(F17=0,,F17/E17-1) -> 0 | I17: décembre | J17: =SUMIFS(Import!F:F,Import!D:D,'Indicateurs transport'!B17) -> 0 | K17: =SUMIFS(Import!F:F,Import!D:D,'Indicateurs transport'!C17) -> 0 | L17: =IF(K17=0,,K17/J17-1) -> 0 | N17: décembre | O17: =IFERROR(J17/E17, 0) -> 0 | P17: =IFERROR(K17/F17, 0) -> 0 | Q17: =IF(P17=0,,P17/O17-1) -> 0 | S17: décembre | T17: =SUMIFS(Import!$S$2:$S$1482,Import!$D$2:$D$1482,'Indicateurs transport'!B17) -> 0 | U17: =SUMIFS(Import!$S$2:$S$1482,Import!$D$2:$D$1482,'Indicateurs transport'!C17) -> 0 | V17: =IF(U17=0,,U17/T17-1) -> 0 | X17: décembre | Y17: =IF(T17=0,,T17/E17) -> 0 | Z17: =IF(U17=0,,U17/F17) -> 0 | AA17: =IF(Z17=0,,Z17/Y17-1) -> 0
D18: Cumul 9 mois | E18: =SUM(E6:E14) -> 455 | F18: =SUM(F6:F14) -> 1026 | I18: Cumul 9 mois | J18: =SUM(J6:J14) -> 150536 | K18: =SUM(K6:K14) -> 333652 | N18: Moyenne 9 mois | O18: =AVERAGE(O6:O17) -> 257.23763 | P18: =AVERAGE(P6:P17) -> 242.42233 | S18: Cumul 9 mois | T18: =SUM(T6:T14) -> 150139.21 | U18: =SUM(U6:U14) -> 373971.12 | X18: Cumul 9 mois | Y18: =IF(T18=0,,T18/E18) -> 329.97629 | Z18: =IF(U18=0,,U18/F18) -> 364.49427
D19: Total | E19: =SUM(E6:E17) -> 455 | F19: =SUM(F6:F17) -> 1026 | I19: total | J19: =SUM(J6:J17) -> 150536 | K19: =SUM(K6:K17) -> 333652 | N19: Total | O19: =SUM(O6:O17) -> 3086.8515 | P19: =SUM(P6:P17) -> 2909.0679 | S19: Total | T19: =SUM(T6:T17) -> 150139.21 | U19: =SUM(U6:U17) -> 373971.12 | X19: Total | Y19: =SUM(Y6:Y17) -> 3018.559 | Z19: =SUM(Z6:Z17) -> 3285.1006
E22: 6. Coût total Transport (€) | J22: 7. Prix moyen transport (€/OT) | O22: 8. Emission GES (kg eq CO2 émis )
E23: 2021 | F23: 2022 | G23: %A/A-1 | J23: 2021 | K23: 2022 | L23: %A/A-1 | O23: 2021 | P23: 2022 | Q23: %A/A-1
D24: janvier | E24: =SUMIFS(Import!$P$2:$P$1482,Import!$D$2:$D$1482,B6) -> 8824 | F24: =SUMIFS(Import!$P$2:$P$1482,Import!$D$2:$D$1482,C6) -> 5047 | G24: =IF(F24=0,,F24/E24-1) -> -0.42803717 | I24: janvier | J24: =IF(E6=0,,E24/E6) -> 284.64516 | K24: =IF(F6=0,,F24/F6) -> 157.71875 | L24: =IF(K24=0,,K24/J24-1) -> -0.44591101 | N24: janvier | O24: =SUMIFS(Import!$O$2:$O$1482,Import!$D$2:$D$1482,B6) -> 596.95981 | P24: =SUMIFS(Import!$O$2:$O$1482,Import!$D$2:$D$1482,C6) -> 354.97536 | Q24: =IF(P24=0,,P24/O24-1) -> -0.40536138
D25: février | E25: =SUMIFS(Import!$P$2:$P$1482,Import!$D$2:$D$1482,B7) -> 6418.5 | F25: =SUMIFS(Import!$P$2:$P$1482,Import!$D$2:$D$1482,C7) -> 11257 | G25: =IF(F25=0,,F25/E25-1) -> 0.75383657 | I25: février | J25: =IF(E7=0,,E25/E7) -> 152.82143 | K25: =IF(F7=0,,F25/F7) -> 163.14493 | L25: =IF(K25=0,,K25/J25-1) -> 0.067552692 | N25: février | O25: =SUMIFS(Import!$O$2:$O$1482,Import!$D$2:$D$1482,B7) -> 528.44577 | P25: =SUMIFS(Import!$O$2:$O$1482,Import!$D$2:$D$1482,C7) -> 609.08467 | Q25: =IF(P25=0,,P25/O25-1) -> 0.15259638
D26: mars | E26: =SUMIFS(Import!$P$2:$P$1482,Import!$D$2:$D$1482,B8) -> 9392.21 | F26: =SUMIFS(Import!$P$2:$P$1482,Import!$D$2:$D$1482,C8) -> 25338.7 | G26: =IF(F26=0,,F26/E26-1) -> 1.6978421 | I26: mars | J26: =IF(E8=0,,E26/E8) -> 146.75328 | K26: =IF(F8=0,,F26/F8) -> 179.70709 | L26: =IF(K26=0,,K26/J26-1) -> 0.22455246 | N26: mars | O26: =SUMIFS(Import!$O$2:$O$1482,Import!$D$2:$D$1482,B8) -> 598.28948 | P26: =SUMIFS(Import!$O$2:$O$1482,Import!$D$2:$D$1482,C8) -> 1281.4501 | Q26: =IF(P26=0,,P26/O26-1) -> 1.1418563
D27: avril | E27: =SUMIFS(Import!$P$2:$P$1482,Import!$D$2:$D$1482,B9) -> 8219.54 | F27: =SUMIFS(Import!$P$2:$P$1482,Import!$D$2:$D$1482,C9) -> 23985.6 | G27: =IF(F27=0,,F27/E27-1) -> 1.9181195 | I27: avril | J27: =IF(E9=0,,E27/E9) -> 158.06808 | K27: =IF(F9=0,,F27/F9) -> 187.3875 | L27: =IF(K27=0,,K27/J27-1) -> 0.18548605 | N27: avril | O27: =SUMIFS(Import!$O$2:$O$1482,Import!$D$2:$D$1482,B9) -> 422.54826 | P27: =SUMIFS(Import!$O$2:$O$1482,Import!$D$2:$D$1482,C9) -> 1479.1594 | Q27: =IF(P27=0,,P27/O27-1) -> 2.5005692
D28: mai | E28: =SUMIFS(Import!$P$2:$P$1482,Import!$D$2:$D$1482,B10) -> 8741.37 | F28: =SUMIFS(Import!$P$2:$P$1482,Import!$D$2:$D$1482,C10) -> 28300.6 | G28: =IF(F28=0,,F28/E28-1) -> 2.2375474 | I28: mai | J28: =IF(E10=0,,E28/E10) -> 161.87722 | K28: =IF(F10=0,,F28/F10) -> 195.17655 | L28: =IF(K28=0,,K28/J28-1) -> 0.20570732 | N28: mai | O28: =SUMIFS(Import!$O$2:$O$1482,Import!$D$2:$D$1482,B10) -> 410.64473 | P28: =SUMIFS(Import!$O$2:$O$1482,Import!$D$2:$D$1482,C10) -> 1432.6033 | Q28: =IF(P28=0,,P28/O28-1) -> 2.4886683
D29: juin | E29: =SUMIFS(Import!$P$2:$P$1482,Import!$D$2:$D$1482,B11) -> 10039.62 | F29: =SUMIFS(Import!$P$2:$P$1482,Import!$D$2:$D$1482,C11) -> 36818.6 | G29: =IF(F29=0,,F29/E29-1) -> 2.66733 | I29: juin | J29: =IF(E11=0,,E29/E11) -> 170.16305 | K29: =IF(F11=0,,F29/F11) -> 220.47066 | L29: =IF(K29=0,,K29/J29-1) -> 0.29564355 | N29: juin | O29: =SUMIFS(Import!$O$2:$O$1482,Import!$D$2:$D$1482,B11) -> 533.07539 | P29: =SUMIFS(Import!$O$2:$O$1482,Import!$D$2:$D$1482,C11) -> 2077.731 | Q29: =IF(P29=0,,P29/O29-1) -> 2.8976307
D30: juillet | E30: =SUMIFS(Import!$P$2:$P$1482,Import!$D$2:$D$1482,B12) -> 7900 | F30: =SUMIFS(Import!$P$2:$P$1482,Import!$D$2:$D$1482,C12) -> 26666.9 | G30: =IF(F30=0,,F30/E30-1) -> 2.375557 | I30: juillet | J30: =IF(E12=0,,E30/E12) -> 158 | K30: =IF(F12=0,,F30/F12) -> 225.99068 | L30: =IF(K30=0,,K30/J30-1) -> 0.43032075 | N30: juillet | O30: =SUMIFS(Import!$O$2:$O$1482,Import!$D$2:$D$1482,B12) -> 491.67252 | P30: =SUMIFS(Import!$O$2:$O$1482,Import!$D$2:$D$1482,C12) -> 1444.6724 | Q30: =IF(P30=0,,P30/O30-1) -> 1.9382818
D31: aout | E31: =SUMIFS(Import!$P$2:$P$1482,Import!$D$2:$D$1482,B13) -> 8494.72 | F31: =SUMIFS(Import!$P$2:$P$1482,Import!$D$2:$D$1482,C13) -> 25942 | G31: =IF(F31=0,,F31/E31-1) -> 2.053897 | I31: aout | J31: =IF(E13=0,,E31/E13) -> 154.44945 | K31: =IF(F13=0,,F31/F13) -> 216.18333 | L31: =IF(K31=0,,K31/J31-1) -> 0.3997028 | N31: aout | O31: =SUMIFS(Import!$O$2:$O$1482,Import!$D$2:$D$1482,B13) -> 648.24623 | P31: =SUMIFS(Import!$O$2:$O$1482,Import!$D$2:$D$1482,C13) -> 1690.3604 | Q31: =IF(P31=0,,P31/O31-1) -> 1.60759
D32: septembre | E32: =SUMIFS(Import!$P$2:$P$1482,Import!$D$2:$D$1482,B14) -> 7690 | F32: =SUMIFS(Import!$P$2:$P$1482,Import!$D$2:$D$1482,C14) -> 22470 | G32: =IF(F32=0,,F32/E32-1) -> 1.9219766 | I32: septembre | J32: =IF(E14=0,,E32/E14) -> 160.20833 | K32: =IF(F14=0,,F32/F14) -> 211.98113 | L32: =IF(K32=0,,K32/J32-1) -> 0.32315921 | N32: septembre | O32: =SUMIFS(Import!$O$2:$O$1482,Import!$D$2:$D$1482,B14) -> 511.84676 | P32: =SUMIFS(Import!$O$2:$O$1482,Import!$D$2:$D$1482,C14) -> 1473.1871 | Q32: =IF(P32=0,,P32/O32-1) -> 1.8781799
D33: octobre | E33: =SUMIFS(Import!$P$2:$P$1482,Import!$D$2:$D$1482,B15) -> 0 | F33: =SUMIFS(Import!$P$2:$P$1482,Import!$D$2:$D$1482,C15) -> 0 | G33: =IF(F33=0,,F33/E33-1) -> 0 | I33: octobre | J33: =IF(E15=0,,E33/E15) -> 0 | K33: =IF(F15=0,,F33/F15) -> 0 | L33: =IF(K33=0,,K33/J33-1) -> 0 | N33: octobre | O33: =SUMIFS(Import!$O$2:$O$1482,Import!$D$2:$D$1482,B15) -> 0 | P33: =SUMIFS(Import!$O$2:$O$1482,Import!$D$2:$D$1482,C15) -> 0 | Q33: =IF(P33=0,,P33/O33-1) -> 0
D34: novembre | E34: =SUMIFS(Import!$P$2:$P$1482,Import!$D$2:$D$1482,B16) -> 0 | F34: =SUMIFS(Import!$P$2:$P$1482,Import!$D$2:$D$1482,C16) -> 0 | G34: =IF(F34=0,,F34/E34-1) -> 0 | I34: novembre | J34: =IF(E16=0,,E34/E16) -> 0 | K34: =IF(F16=0,,F34/F16) -> 0 | L34: =IF(K34=0,,K34/J34-1) -> 0 | N34: novembre | O34: =SUMIFS(Import!$O$2:$O$1482,Import!$D$2:$D$1482,B16) -> 0 | P34: =SUMIFS(Import!$O$2:$O$1482,Import!$D$2:$D$1482,C16) -> 0 | Q34: =IF(P34=0,,P34/O34-1) -> 0
D35: décembre | E35: =SUMIFS(Import!$P$2:$P$1482,Import!$D$2:$D$1482,B17) -> 0 | F35: =SUMIFS(Import!$P$2:$P$1482,Import!$D$2:$D$1482,C17) -> 0 | G35: =IF(F35=0,,F35/E35-1) -> 0 | I35: décembre | J35: =IF(E17=0,,E35/E17) -> 0 | K35: =IF(F17=0,,F35/F17) -> 0 | L35: =IF(K35=0,,K35/J35-1) -> 0 | N35: décembre | O35: =SUMIFS(Import!$O$2:$O$1482,Import!$D$2:$D$1482,B17) -> 0 | P35: =SUMIFS(Import!$O$2:$O$1482,Import!$D$2:$D$1482,C17) -> 0 | Q35: =IF(P35=0,,P35/O35-1) -> 0
D36: Cumul 9 mois | E36: =SUM(E24:E32) -> 75719.96 | F36: =SUM(F24:F32) -> 205826.4 | I36: Cumul 9 mois | J36: =IF(E18=0,,E36/E18) -> 166.41749 | K36: =IF(F18=0,,F36/F18) -> 200.61053 | N36: Cumul 9 mois | O36: =SUM(O24:O32) -> 4741.7289 | P36: =SUM(P24:P32) -> 11843.224
D37: Total | E37: =SUM(E24:E35) -> 75719.96 | F37: =SUM(F24:F35) -> 205826.4 | I37: Total | J37: =SUM(J24:J35) -> 1546.986 | K37: =SUM(K24:K35) -> 1757.7606 | N37: Total | O37: =SUM(O24:O35) -> 4741.7289 | P37: =SUM(P24:P35) -> 11843.224
D42: Informations sur les modes de calcul des indicateurs 3, 5 et 7 -L'indicateur 3 est calculé à partir des indicateurs 1 et 2. -L'indicateur 5 est calculé à partir des indicateurs 1 et 4. -L'indicateur 7 est calculé à partir des indicateurs 1 et 6.

Sheet Taux émission CO2e
A1: Taux Emissions CO2e par type de véhicule
A4: 1er segment transport
A5: Type TRANSPORT | B5: % répartition segment 1 | C5: 1er segment transport | D5: taux d'émission de CO2e par unité transportée et par km (kg/TxKM)
A6: AFF | B6: 1 | C6: Articulé - 44 à 60 tonnes - Diesel routier, incorporation 7 % de biodiesel | D6: 0.0674
A7: V | B7: 1 | C7: VUL - < 3,5 tonnes - Essence | D7: 1.16
A8: C | B8: 1 | C8: Rigide - 3,5 à 7,5 tonnes - Diesel routier, incorporation 7 % de biodiesel | D8: 0.378
A9: GV | B9: 1 | C9: Rigide - 7,5 à 12 tonnes - Diesel routier, incorporation 7 % de biodiesel | D9: 0.241
A10: NAV | B10: 1 | C10: VUL - < 3,5 tonnes - Essence | D10: 1.16
A11: PL | B11: 1 | C11: Rigide - 12 à 20 tonnes - Diesel routier, incorporation 7 % de biodiesel | D11: 0.16
A12: PLR | B12: 1 | C12: Rigide - 12 à 20 tonnes - Diesel routier, incorporation 7 % de biodiesel | D12: 0.16
A13: PALEX | B13: 0.3 | C13: Rigide - 12 à 20 tonnes - Diesel routier, incorporation 7 % de biodiesel | D13: 0.16
A14: PAEX | B14: 0.3 | C14: Rigide - 12 à 20 tonnes - Diesel routier, incorporation 7 % de biodiesel | D14: 0.16
A15: POLE | B15: 0.3 | C15: Rigide - 12 à 20 tonnes - Diesel routier, incorporation 7 % de biodiesel | D15: 0.16
A16: POLE DCR | B16: 0.3 | C16: Rigide - 12 à 20 tonnes - Diesel routier, incorporation 7 % de biodiesel | D16: 0.16
A19: 2nd segment transport | C19: si 0% , l'intégralité du transport est réalisé avec le mode de transport défini en segment 1
A20: Type TRANSPORT | B20: % répartition segment 2 | C20: 2nd segment transport | D20: taux d'émission de CO2e par unité transportée et par km (kg/TxKM)
A21: AFF | B21: 0 | D21: 0
A22: V | B22: 0 | D22: 0
A23: C | B23: 0 | D23: 0
A24: GV | B24: 0 | D24: 0
A25: NAV | B25: 0 | D25: 0
A26: PL | B26: 0 | D26: 0
A27: PLR | B27: 0 | D27: 0
A28: PALEX | B28: 0.7 | C28: Articulé - 44 à 60 tonnes - Diesel routier, incorporation 7 % de biodiesel | D28: =D6 -> 0.0674
A29: PAEX | B29: 0.7 | C29: Articulé - 44 à 60 tonnes - Diesel routier, incorporation 7 % de biodiesel | D29: =D28 -> 0.0674
A30: POLE | B30: 0.7 | C30: Articulé - 44 à 60 tonnes - Diesel routier, incorporation 7 % de biodiesel | D30: =D29 -> 0.0674
A31: POLE DCR | B31: 0.7 | C31: Articulé - 44 à 60 tonnes - Diesel routier, incorporation 7 % de biodiesel | D31: =D30 -> 0.0674

Sheet TCD_OT
A3: Nombre de Numero ot | B3: Étiquettes de colonnes
A4: Étiquettes de lignes | B4: 2021 | C4: 2022 | D4: Total général
A5: janvier | B5: 31 | C5: 32 | D5: 63
A6: février | B6: 42 | C6: 69 | D6: 111
A7: mars | B7: 64 | C7: 141 | D7: 205
A8: avril | B8: 52 | C8: 128 | D8: 180
A9: mai | B9: 54 | C9: 145 | D9: 199
A10: juin | B10: 59 | C10: 167 | D10: 226
A11: juillet | B11: 50 | C11: 118 | D11: 168
A12: août | B12: 55 | C12: 120 | D12: 175
A13: septembre | B13: 48 | C13: 106 | D13: 154
A14: Total général | B14: 455 | C14: 1026 | D14: 1481
A17: Variation valeur total 2021vs2022 | B17: =C14-B14 -> 571
A18: % 2021vs2022 | B18: =(C14-B14)/B14 -> 1.2549451

Sheet TCD_Poids(Kg)
A3: Somme de Poids OT (kg) | B3: Étiquettes de colonnes
A4: Étiquettes de lignes | B4: 2021 | C4: 2022 | D4: Total général
A5: janvier | B5: 18053 | C5: 10517 | D5: 28570
A6: février | B6: 12198 | C6: 17805 | D6: 30003
A7: mars | B7: 17800 | C7: 39619 | D7: 57419
A8: avril | B8: 14855 | C8: 45889 | D8: 60744
A9: mai | B9: 15055 | C9: 47442 | D9: 62497
A10: juin | B10: 19180 | C10: 54949 | D10: 74129
A11: juillet | B11: 14840 | C11: 34775 | D11: 49615
A12: août | B12: 20230 | C12: 43452 | D12: 63682
A13: septembre | B13: 18325 | C13: 39204 | D13: 57529
A14: Total général | B14: 150536 | C14: 333652 | D14: 484188
A17: Variation valeur total 2021vs2022 | B17: =C14-B14 -> 183116
A18: % 2021vs2022 | B18: =(C14-B14)/B14 -> 1.2164266

Sheet TCD_Km
A3: Somme de Distance en km | B3: Étiquettes de colonnes
A4: Étiquettes de lignes | B4: 2021 | C4: 2022 | D4: Total général
A5: janvier | B5: 12548.985 | C5: 11522.19 | D5: 24071.175
A6: février | B6: 16191.553 | C6: 25546.339 | D6: 41737.892
A7: mars | B7: 20002.071 | C7: 51154.93 | D7: 71157.001
A8: avril | B8: 17638.505 | C8: 43743.548 | D8: 61382.053
A9: mai | B9: 16365.549 | C9: 50423.278 | D9: 66788.827
A10: juin | B10: 17451.166 | C10: 61226.338 | D10: 78677.504
A11: juillet | B11: 17036.291 | C11: 45173.56 | D11: 62209.851
A12: août | B12: 18325.828 | C12: 45922.895 | D12: 64248.723
A13: septembre | B13: 14579.262 | C13: 39258.042 | D13: 53837.304
A14: Total général | B14: 150139.21 | C14: 373971.12 | D14: 524110.33
A17: Variation valeur total 2021vs2022 | B17: =C14-B14 -> 223831.91
A18: % 2021vs2022 | B18: =(C14-B14)/B14 -> 1.4908291

Sheet TCD_Coût_Transport
A3: Somme de Coût OT (€) | B3: Étiquettes de colonnes
A4: Étiquettes de lignes | B4: 2021 | C4: 2022 | D4: Total général
A5: janvier | B5: 8824 | C5: 5047 | D5: 13871
A6: février | B6: 6418.5 | C6: 11257 | D6: 17675.5
A7: mars | B7: 9392.21 | C7: 25338.7 | D7: 34730.91
A8: avril | B8: 8219.54 | C8: 23985.6 | D8: 32205.14
A9: mai | B9: 8741.37 | C9: 28300.6 | D9: 37041.97
A10: juin | B10: 10039.62 | C10: 36818.6 | D10: 46858.22
A11: juillet | B11: 7900 | C11: 26666.9 | D11: 34566.9
A12: août | B12: 8494.72 | C12: 25942 | D12: 34436.72
A13: septembre | B13: 7690 | C13: 22470 | D13: 30160
A14: Total général | B14: 75719.96 | C14: 205826.4 | D14: 281546.36
A17: Variation valeur total 2021vs2022 | B17: =C14-B14 -> 130106.44
A18: % 2021vs2022 | B18: =(C14-B14)/B14 -> 1.7182582

Sheet TCD_CO2
A3: Somme de Bilan CO2 | B3: Étiquettes de colonnes
A4: Étiquettes de lignes | B4: 2021 | C4: 2022 | D4: Total général
A5: janvier | B5: 596.95981 | C5: 354.97536 | D5: 951.93517
A6: février | B6: 528.44577 | C6: 609.08467 | D6: 1137.5304
A7: mars | B7: 598.28948 | C7: 1281.4501 | D7: 1879.7396
A8: avril | B8: 422.54826 | C8: 1479.1594 | D8: 1901.7077
A9: mai | B9: 410.64473 | C9: 1432.6033 | D9: 1843.248
A10: juin | B10: 533.07539 | C10: 2077.731 | D10: 2610.8064
A11: juillet | B11: 491.67252 | C11: 1444.6724 | D11: 1936.345
A12: août | B12: 648.24623 | C12: 1690.3604 | D12: 2338.6066
A13: septembre | B13: 511.84676 | C13: 1473.1871 | D13: 1985.0338
A14: Total général | B14: 4741.7289 | C14: 11843.224 | D14: 16584.953
A17: Variation valeur total 2021vs2022 | B17: =C14-B14 -> 7101.4947
A18: % 2021vs2022 | B18: =(C14-B14)/B14 -> 1.4976594
